<?xml version="1.0" encoding="utf-8"?>
<!-- This URDF was automatically created by SolidWorks to URDF Exporter! Originally created by Stephen Brawner (brawner@gmail.com) 
     Commit Version: 1.6.0-4-g7f85cfe  Build Version: 1.6.7995.38578
     For more information, please see http://wiki.ros.org/sw_urdf_exporter -->
<robot
  name="griebot0502">
  <link
    name="base_link">
    <inertial>
      <origin
        xyz="0.0012171 -0.0073486 0.087541"
        rpy="0 0 0" />
      <mass
        value="2" />
      <inertia
        ixx="0.012022"
        ixy="9.4559E-06"
        ixz="-9.2257E-05"
        iyy="0.014905"
        iyz="0.00080386"
        izz="0.005398" />
    </inertial>
    <visual>
      <origin
        xyz="0 0 0"
        rpy="0 0 0" />
      <geometry>
        <mesh
          filename="package://griebot0502/meshes/base_link.STL" />
      </geometry>
      <material
        name="">
        <color
          rgba="0.53725 0.34902 0.33725 1" />
      </material>
    </visual>
    <collision>
      <origin
        xyz="0 0 0"
        rpy="0 0 0" />
      <geometry>
        <mesh
          filename="package://griebot0502/meshes/base_link.STL" />
      </geometry>
    </collision>
  </link>
  <link
    name="Rhip">
    <inertial>
      <origin
        xyz="-0.0015662 -0.0035452 0.018069"
        rpy="0 0 0" />
      <mass
        value="0.79106" />
      <inertia
        ixx="0.00058107"
        ixy="3.1255E-05"
        ixz="-1.0617E-05"
        iyy="0.00052094"
        iyz="0.00013177"
        izz="0.00040317" />
    </inertial>
    <visual>
      <origin
        xyz="0 0 0"
        rpy="0 0 0" />
      <geometry>
        <mesh
          filename="package://griebot0502/meshes/Rhip.STL" />
      </geometry>
      <material
        name="">
        <color
          rgba="0.89412 0.91373 0.92941 1" />
      </material>
    </visual>
    <collision>
      <origin
        xyz="0 0 0"
        rpy="0 0 0" />
      <geometry>
        <mesh
          filename="package://griebot0502/meshes/Rhip.STL" />
      </geometry>
    </collision>
  </link>
  <joint
    name="Rhipjoint"
    type="revolute">
    <origin
      xyz="0.058289 0.013792 -0.050716"
      rpy="1.6546 0.013805 0.0011592" />
    <parent
      link="base_link" />
    <child
      link="Rhip" />
    <axis
      xyz="0 0 -1" />
    <limit
      lower="-3"
      upper="3"
      effort="110"
      velocity="2" />
  </joint>
  <link
    name="Rthigh">
    <inertial>
      <origin
        xyz="-0.00030237 -0.062783 -0.0017526"
        rpy="0 0 0" />
      <mass
        value="0.71234" />
      <inertia
        ixx="0.00098396"
        ixy="-4.2512E-06"
        ixz="-3.6167E-07"
        iyy="0.00018103"
        iyz="1.0499E-05"
        izz="0.001062" />
    </inertial>
    <visual>
      <origin
        xyz="0 0 0"
        rpy="0 0 0" />
      <geometry>
        <mesh
          filename="package://griebot0502/meshes/Rthigh.STL" />
      </geometry>
      <material
        name="">
        <color
          rgba="0.89412 0.91373 0.92941 1" />
      </material>
    </visual>
    <collision>
      <origin
        xyz="0 0 0"
        rpy="0 0 0" />
      <geometry>
        <mesh
          filename="package://griebot0502/meshes/Rthigh.STL" />
      </geometry>
    </collision>
  </link>
  <joint
    name="Rthighjoint"
    type="revolute">
    <origin
      xyz="-0.001 -0.035 -0.0005"
      rpy="0.037192 0 0" />
    <parent
      link="Rhip" />
    <child
      link="Rthigh" />
    <axis
      xyz="-1 0 0" />
    <limit
      lower="-3"
      upper="3"
      effort="110"
      velocity="2" />
  </joint>
  <link
    name="Rshank">
    <inertial>
      <origin
        xyz="3.2595E-10 -0.063425 0.0012181"
        rpy="0 0 0" />
      <mass
        value="0.97116" />
      <inertia
        ixx="0.0014338"
        ixy="7.7522E-12"
        ixz="2.6766E-11"
        iyy="0.00032647"
        iyz="-1.2141E-05"
        izz="0.0016081" />
    </inertial>
    <visual>
      <origin
        xyz="0 0 0"
        rpy="0 0 0" />
      <geometry>
        <mesh
          filename="package://griebot0502/meshes/Rshank.STL" />
      </geometry>
      <material
        name="">
        <color
          rgba="0.89412 0.91373 0.92941 1" />
      </material>
    </visual>
    <collision>
      <origin
        xyz="0 0 0"
        rpy="0 0 0" />
      <geometry>
        <mesh
          filename="package://griebot0502/meshes/Rshank.STL" />
      </geometry>
    </collision>
  </link>
  <joint
    name="Rshankjoint"
    type="revolute">
    <origin
      xyz="0.0019 -0.14107 -0.0005"
      rpy="0.034967 0 0" />
    <parent
      link="Rthigh" />
    <child
      link="Rshank" />
    <axis
      xyz="-1 0 0" />
    <limit
      lower="-3"
      upper="3"
      effort="110"
      velocity="2" />
  </joint>
  <link
    name="Rfeet">
    <inertial>
      <origin
        xyz="-5.2389E-05 -0.051491 0.032203"
        rpy="0 0 0" />
      <mass
        value="0.8" />
      <inertia
        ixx="0.0031769"
        ixy="3.3687E-06"
        ixz="-2.1066E-06"
        iyy="0.0025047"
        iyz="0.00075503"
        izz="0.0010865" />
    </inertial>
    <visual>
      <origin
        xyz="0 0 0"
        rpy="0 0 0" />
      <geometry>
        <mesh
          filename="package://griebot0502/meshes/Rfeet.STL" />
      </geometry>
      <material
        name="">
        <color
          rgba="0.53725 0.34902 0.33725 1" />
      </material>
    </visual>
    <collision>
      <origin
        xyz="0 0 0"
        rpy="0 0 0" />
      <geometry>
        <mesh
          filename="package://griebot0502/meshes/Rfeet.STL" />
      </geometry>
    </collision>
  </link>
  <joint
    name="Rfeetjoint"
    type="revolute">
    <origin
      xyz="0.001 -0.135 0"
      rpy="-3.0694 0 3.1416" />
    <parent
      link="Rshank" />
    <child
      link="Rfeet" />
    <axis
      xyz="-1 0 0" />
    <limit
      lower="-3"
      upper="3"
      effort="110"
      velocity="2" />
  </joint>
  <link
    name="Lhip">
    <inertial>
      <origin
        xyz="-0.0015118 -0.0035452 -0.018069"
        rpy="0 0 0" />
      <mass
        value="0.79106" />
      <inertia
        ixx="0.00058107"
        ixy="3.1255E-05"
        ixz="1.0617E-05"
        iyy="0.00052094"
        iyz="-0.00013177"
        izz="0.00040317" />
    </inertial>
    <visual>
      <origin
        xyz="0 0 0"
        rpy="0 0 0" />
      <geometry>
        <mesh
          filename="package://griebot0502/meshes/Lhip.STL" />
      </geometry>
      <material
        name="">
        <color
          rgba="0.89412 0.91373 0.92941 1" />
      </material>
    </visual>
    <collision>
      <origin
        xyz="0 0 0"
        rpy="0 0 0" />
      <geometry>
        <mesh
          filename="package://griebot0502/meshes/Lhip.STL" />
      </geometry>
    </collision>
  </link>
  <joint
    name="Lhipjoint"
    type="revolute">
    <origin
      xyz="-0.059699 0.014402 -0.049024"
      rpy="1.487 -0.013805 -3.1404" />
    <parent
      link="base_link" />
    <child
      link="Lhip" />
    <axis
      xyz="0 0 1" />
    <limit
      lower="-3"
      upper="3"
      effort="110"
      velocity="2" />
  </joint>
  <link
    name="Lthigh">
    <inertial>
      <origin
        xyz="-0.0003203 -0.062783 -0.0017283"
        rpy="0 0 0" />
      <mass
        value="0.71234" />
      <inertia
        ixx="0.00098396"
        ixy="-4.2572E-06"
        ixz="-3.6167E-07"
        iyy="0.00018103"
        iyz="1.0499E-05"
        izz="0.001062" />
    </inertial>
    <visual>
      <origin
        xyz="0 0 0"
        rpy="0 0 0" />
      <geometry>
        <mesh
          filename="package://griebot0502/meshes/Lthigh.STL" />
      </geometry>
      <material
        name="">
        <color
          rgba="0.89412 0.91373 0.92941 1" />
      </material>
    </visual>
    <collision>
      <origin
        xyz="0 0 0"
        rpy="0 0 0" />
      <geometry>
        <mesh
          filename="package://griebot0502/meshes/Lthigh.STL" />
      </geometry>
    </collision>
  </link>
  <joint
    name="Lthighjoint"
    type="revolute">
    <origin
      xyz="0.00025 -0.035 0.0005"
      rpy="-3.1044 0 -3.1416" />
    <parent
      link="Lhip" />
    <child
      link="Lthigh" />
    <axis
      xyz="-1 0 0" />
    <limit
      lower="-3"
      upper="3"
      effort="110"
      velocity="2" />
  </joint>
  <link
    name="Lshank">
    <inertial>
      <origin
        xyz="3.2595E-10 -0.063425 0.0012181"
        rpy="0 0 0" />
      <mass
        value="0.97116" />
      <inertia
        ixx="0.0014338"
        ixy="7.7522E-12"
        ixz="2.6766E-11"
        iyy="0.00032647"
        iyz="-1.2141E-05"
        izz="0.0016081" />
    </inertial>
    <visual>
      <origin
        xyz="0 0 0"
        rpy="0 0 0" />
      <geometry>
        <mesh
          filename="package://griebot0502/meshes/Lshank.STL" />
      </geometry>
      <material
        name="">
        <color
          rgba="0.89412 0.91373 0.92941 1" />
      </material>
    </visual>
    <collision>
      <origin
        xyz="0 0 0"
        rpy="0 0 0" />
      <geometry>
        <mesh
          filename="package://griebot0502/meshes/Lshank.STL" />
      </geometry>
    </collision>
  </link>
  <joint
    name="Lshankjoint"
    type="revolute">
    <origin
      xyz="-0.0004 -0.14107 0"
      rpy="0.034967 0 0" />
    <parent
      link="Lthigh" />
    <child
      link="Lshank" />
    <axis
      xyz="1 0 0" />
    <limit
      lower="-3"
      upper="3"
      effort="110"
      velocity="2" />
  </joint>
  <link
    name="Lfeet">
    <inertial>
      <origin
        xyz="-5.2389E-05 -0.051491 0.032203"
        rpy="0 0 0" />
      <mass
        value="0.8" />
      <inertia
        ixx="0.0031769"
        ixy="3.3687E-06"
        ixz="-2.1066E-06"
        iyy="0.0025047"
        iyz="0.00075503"
        izz="0.0010865" />
    </inertial>
    <visual>
      <origin
        xyz="0 0 0"
        rpy="0 0 0" />
      <geometry>
        <mesh
          filename="package://griebot0502/meshes/Lfeet.STL" />
      </geometry>
      <material
        name="">
        <color
          rgba="0.53725 0.34902 0.33725 1" />
      </material>
    </visual>
    <collision>
      <origin
        xyz="0 0 0"
        rpy="0 0 0" />
      <geometry>
        <mesh
          filename="package://griebot0502/meshes/Lfeet.STL" />
      </geometry>
    </collision>
  </link>
  <joint
    name="Lfeetjoint"
    type="revolute">
    <origin
      xyz="-0.001 -0.135 0"
      rpy="-3.0694 0 -3.1416" />
    <parent
      link="Lshank" />
    <child
      link="Lfeet" />
    <axis
      xyz="-1 0 0" />
    <limit
      lower="-3"
      upper="3"
      effort="110"
      velocity="2" />
  </joint>
</robot>